Workbook

Sheet Article
A1: SKU | B1: LibSKU | C1: LibGFam | D1: UnCommande | E1: OLeadTime | F1: Fournisseur ID
A2: 115600 | B2: TUBE PVC | C2: SALLE DE BAINS | D2: PIECE | E2: 14 | F2: 15461
A3: 129208 | B3: COUDE PVC | C3: SALLE DE BAINS | D3: UVC | E3: 14 | F3: 15461
A4: 300380 | B4: CARTOUCHE SILICONE | C4: SALLE DE BAINS | D4: UVC | E4: 14 | F4: 16783
A5: 23393 | B5: CLIPS POUR PLINTHE | C5: SALLE DE BAINS | D5: UVC | E5: 7 | F5: 14673
A6: 26764 | B6: TRINGLE CHROME | C6: SALLE DE BAINS | D6: UVC | E6: 7 | F6: 12576
A7: 53934 | B7: EQUERRE FIXATION | C7: SALLE DE BAINS | D7: UVC | E7: 14 | F7: 14673
A8: 78699 | B8: POIGNEE CHROME | C8: SALLE DE BAINS | D8: UVC | E8: 7 | F8: 14673
A9: 78869 | B9: SACH. PLIANT | C9: SALLE DE BAINS | D9: UVC | E9: 7 | F9: 14673
A10: 141622 | B10: BONDE LAVABO | C10: SALLE DE BAINS | D10: UVC | E10: 7 | F10: 12576
A11: 141626 | B11: KIT DE FIXATION | C11: SALLE DE BAINS | D11: UVC | E11: 7 | F11: 14673
A12: 141791 | B12: BACHE DE PROTECTION | C12: SALLE DE BAINS | D12: UVC | E12: 14 | F12: 12576
A13: 141846 | B13: MITIGEUR LAVABO | C13: SALLE DE BAINS | D13: UVC | E13: 14 | F13: 12576
... A31: 614993 | B31: PLINTHE INOX | C31: CUISINE | D31: UVC | E31: 14 | F31: 12576

Sheet Shop
A1: Location ID | B1: Lib Location | C1: Distance depuis Entrepôt (km)
A2: 1201 | B2: LA ROCHELLE | C2: 469
A3: 1202 | B3: BAYONNE | C3: 770
A4: 1203 | B4: ARCUEIL | C4: 35
A5: 1204 | B5: NICE ARIANE (Est) | C5: 913
A6: 1205 | B6: VALENCIENNES | C6: 243
A7: 1206 | B7: CREIL | C7: 108
A8: 1207 | B8: LE HAVRE | C8: 231
A9: 1208 | B9: AVIGNON | C9: 661
A10: 1209 | B10: NICE VILLENEUVE LOUBET | C10: 888
A11: 1210 | B11: STRASBOURG NORD | C11: 503
A12: 1211 | B12: TOULON | C12: 809
A13: 1212 | B13: ROUEN | C13: 170
... A19: 1220 | B19: LIMOGES | C19: 388

Sheet Fournisseurs-Magasin
A1: Fournisseur ID | B1: Shop ID | C1: Distance
A2: 12576 | B2: 1201 | C2: 927
A3: 12576 | B3: 1202 | C3: 1155
A4: 12576 | B4: 1203 | C4: 489
A5: 12576 | B5: 1204 | C5: 787
A6: 12576 | B6: 1205 | C6: 487
A7: 12576 | B7: 1206 | C7: 483
A8: 12576 | B8: 1207 | C8: 697
A9: 12576 | B9: 1208 | C9: 721
A10: 12576 | B10: 1209 | C10: 805
A11: 12576 | B11: 1210 | C11: 3
A12: 12576 | B12: 1211 | C12: 869
A13: 12576 | B13: 1212 | C13: 635
... A96: 16783 | B96: 1500 | C96: 134

Sheet Transporteurs
A1: Transporteur ID | B1: Prix Fixe € | C1: €/km au-delà fixe | D1: Colonne1
A2: AFF | B2: 60 | C2: 1.03 | D2: =Table3[[#This Row],[Prix Fixe €]]+Table3[[#This Row],[€/km au-delà fixe]]*DRP_V2!$H$28 -> 60
A3: AV | B3: 75 | C3: 1 | D3: =Table3[[#This Row],[Prix Fixe €]]+Table3[[#This Row],[€/km au-delà fixe]]*DRP_V2!$H$28 -> 75
A4: C | B4: 34 | C4: 1.22 | D4: =Table3[[#This Row],[Prix Fixe €]]+Table3[[#This Row],[€/km au-delà fixe]]*DRP_V2!$H$28 -> 34
A5: GV | B5: 55 | C5: 1.04 | D5: =Table3[[#This Row],[Prix Fixe €]]+Table3[[#This Row],[€/km au-delà fixe]]*DRP_V2!$H$28 -> 55
A6: NAV | B6: 45 | C6: 1.2 | D6: =Table3[[#This Row],[Prix Fixe €]]+Table3[[#This Row],[€/km au-delà fixe]]*DRP_V2!$H$28 -> 45
A7: PL | B7: 68 | C7: 1.01 | D7: =Table3[[#This Row],[Prix Fixe €]]+Table3[[#This Row],[€/km au-delà fixe]]*DRP_V2!$H$28 -> 68
A8: PALEX | B8: 0 | C8: 1.2 | D8: =Table3[[#This Row],[Prix Fixe €]]+Table3[[#This Row],[€/km au-delà fixe]]*DRP_V2!$H$28 -> 0
A9: POLE | B9: 15 | C9: 1.23 | D9: =Table3[[#This Row],[Prix Fixe €]]+Table3[[#This Row],[€/km au-delà fixe]]*DRP_V2!$H$28 -> 15

Sheet Forecast
A1: Location ID | B1: SKU | C1: Date semaine | D1: Demande prévue | E1: cle
A2: 1201 | B2: 23393 | C2: 44739 | D2: 102 | E2: =A2&"-"&B2&"-"&INT(C2) -> 1201-23393-44739
A3: 1201 | B3: 23393 | C3: 44746 | D3: 354 | E3: =A3&"-"&B3&"-"&INT(C3) -> 1201-23393-44746
A4: 1201 | B4: 23393 | C4: 44753 | D4: 168 | E4: =A4&"-"&B4&"-"&INT(C4) -> 1201-23393-44753
A5: 1201 | B5: 23393 | C5: 44760 | D5: 296 | E5: =A5&"-"&B5&"-"&INT(C5) -> 1201-23393-44760
A6: 1201 | B6: 23393 | C6: 44767 | D6: 110 | E6: =A6&"-"&B6&"-"&INT(C6) -> 1201-23393-44767
A7: 1201 | B7: 23393 | C7: 44774 | D7: 100 | E7: =A7&"-"&B7&"-"&INT(C7) -> 1201-23393-44774
A8: 1201 | B8: 23393 | C8: 44781 | D8: 105 | E8: =A8&"-"&B8&"-"&INT(C8) -> 1201-23393-44781
A9: 1201 | B9: 23393 | C9: 44788 | D9: 246 | E9: =A9&"-"&B9&"-"&INT(C9) -> 1201-23393-44788
A10: 1201 | B10: 26764 | C10: 44739 | D10: 111 | E10: =A10&"-"&B10&"-"&INT(C10) -> 1201-26764-44739
A11: 1201 | B11: 26764 | C11: 44746 | D11: 106 | E11: =A11&"-"&B11&"-"&INT(C11) -> 1201-26764-44746
A12: 1201 | B12: 26764 | C12: 44753 | D12: 138 | E12: =A12&"-"&B12&"-"&INT(C12) -> 1201-26764-44753
A13: 1201 | B13: 26764 | C13: 44760 | D13: 107 | E13: =A13&"-"&B13&"-"&INT(C13) -> 1201-26764-44760
... A4102: 1220 | B4102: 614993 | C4102: 44788 | D4102: 6 | E4102: =A4102&"-"&B4102&"-"&INT(C4102) -> 1220-614993-44788

Sheet Commandes_EnCours
A1: Location ID | B1: SKU | C1: Semaine de reception prévue | D1: Quantité Ordre ferme | E1: cle
A2: 1218 | B2: 78869 | C2: 44753 | D2: 35 | E2: =A2&"-"&B2&"-"&INT(C2) -> 1218-78869-44753
A3: 1213 | B3: 78869 | C3: 44753 | D3: 18 | E3: =A3&"-"&B3&"-"&INT(C3) -> 1213-78869-44753
A4: 1212 | B4: 78869 | C4: 44753 | D4: 11 | E4: =A4&"-"&B4&"-"&INT(C4) -> 1212-78869-44753
A5: 1211 | B5: 78869 | C5: 44753 | D5: 28 | E5: =A5&"-"&B5&"-"&INT(C5) -> 1211-78869-44753
A6: 1208 | B6: 78869 | C6: 44753 | D6: 7 | E6: =A6&"-"&B6&"-"&INT(C6) -> 1208-78869-44753
A7: 1206 | B7: 78869 | C7: 44753 | D7: 7 | E7: =A7&"-"&B7&"-"&INT(C7) -> 1206-78869-44753
A8: 1220 | B8: 78869 | C8: 44746 | D8: 25 | E8: =A8&"-"&B8&"-"&INT(C8) -> 1220-78869-44746
A9: 1216 | B9: 78869 | C9: 44746 | D9: 17 | E9: =A9&"-"&B9&"-"&INT(C9) -> 1216-78869-44746
A10: 1214 | B10: 78869 | C10: 44746 | D10: 18 | E10: =A10&"-"&B10&"-"&INT(C10) -> 1214-78869-44746
A11: 1210 | B11: 78869 | C11: 44746 | D11: 35 | E11: =A11&"-"&B11&"-"&INT(C11) -> 1210-78869-44746
A12: 1203 | B12: 78869 | C12: 44746 | D12: 16 | E12: =A12&"-"&B12&"-"&INT(C12) -> 1203-78869-44746
A13: 1201 | B13: 78869 | C13: 44746 | D13: 17 | E13: =A13&"-"&B13&"-"&INT(C13) -> 1201-78869-44746
... A385: 1202 | B385: 115600 | C385: 44739 | D385: 29 | E385: =A385&"-"&B385&"-"&INT(C385) -> 1202-115600-44739

Sheet Stock_S_Encours
A1: Location ID | B1: SKU | C1: Quantité en Stock | D1: Cle
A2: 1201 | B2: 115600 | C2: 64 | D2: =A2&"-"&B2 -> 1201-115600
A3: 1201 | B3: 129208 | C3: 108 | D3: =A3&"-"&B3 -> 1201-129208
A4: 1201 | B4: 300380 | C4: 76 | D4: =A4&"-"&B4 -> 1201-300380
A5: 1201 | B5: 23393 | C5: 114 | D5: =A5&"-"&B5 -> 1201-23393
A6: 1201 | B6: 26764 | C6: 98 | D6: =A6&"-"&B6 -> 1201-26764
A7: 1201 | B7: 53934 | C7: 88 | D7: =A7&"-"&B7 -> 1201-53934
A8: 1201 | B8: 78699 | C8: 80 | D8: =A8&"-"&B8 -> 1201-78699
A9: 1201 | B9: 78869 | C9: 112 | D9: =A9&"-"&B9 -> 1201-78869
A10: 1201 | B10: 141622 | C10: 108 | D10: =A10&"-"&B10 -> 1201-141622
A11: 1201 | B11: 141626 | C11: 90 | D11: =A11&"-"&B11 -> 1201-141626
A12: 1201 | B12: 141791 | C12: 68 | D12: =A12&"-"&B12 -> 1201-141791
A13: 1201 | B13: 141846 | C13: 74 | D13: =A13&"-"&B13 -> 1201-141846
... A509: 1220 | B509: 571521 | C509: 58 | D509: =A509&"-"&B509 -> 1220-571521
A510: 1220 | B510: 614993 | C510: 78 | D510: =DRP_V1!I1 -> 0

Sheet DICODATA
A2: Nb : l’ensemble des quantités dans les tables de faits sont consolidées en unité de commande.
A4: Article | B4: Table de dimension
A5: Nom | B5: Type | C5: Desr
A6: SKU | B6: Int | C6: Identifiant article (PK)
A7: LibSKU | B7: String | C7: Libellé de l'article
A8: LibGFam | B8: String | C8: Famille de l'article
A9: UnCommande | B9: String | C9: Unité de commande
A10: OLeadTime | B10: Int | C10: Lead Time de l'article
A12: Shop | B12: Table de dimension
A13: Nom | B13: Type | C13: Desr
A14: Location ID | B14: Int | C14: Identifiant magasin (PK)
A15: Lib Location | B15: String | C15: Nom/localisation du magasin
A16: Distance depuis Entrepôt (km) | B16: Int | C16: Distance entre le magasin et l'entrepôt
A18: Fournisseurs-Magasin | B18: Table de dimension
A19: Nom | B19: Type | C19: Desr
A20: Fournisseur ID | B20: Int | C20: Identifiant Fournisseur (PK)
A21: Shop ID | B21: String | C21: Identifiant magasin (PK)
A22: Distance | B22: Int | C22: Distance entre le magasin et fournisseur
A24: Transporteur | B24: Table de dimension
A25: Nom | B25: Type | C25: Desr
A26: Transporteur ID | B26: Int | C26: Identifiant Transporteur (PK)
A27: Prix Fixe € | B27: Float | C27: Prix fixe en € pour un transport
A28: €/km au-delà fixe | B28: Float | C28: Prix au km en € au-delà du prix fixe
A30: Forecast | B30: Table de faits
A31: Nom | B31: Type | C31: Desr
A32: Location ID | B32: Int | C32: Identifiant boutique (FK)
A33: SKU | B33: Int | C33: Identifiant article (FK)
A34: Date semaine | B34: Date | C34: Semaine représentée par la date du lundi (FK)
A35: Demande prévue | B35: Date | C35: Quantité de vente prévue aggrégée à la semaine
A37: Commandes_EnCours | B37: Table de faits
A38: Nom | B38: Type | C38: Desr
A39: Location ID | B39: Int | C39: Identifiant boutique (FK)
A40: SKU | B40: Int | C40: Identifiant article (FK)
A41: Semaine de reception prévue | B41: Date | C41: Semaine représentée par la date du lundi (FK)
A42: Quantité Ordre ferme | B42: Int | C42: Quantité commandée aggrégée la semaine
A44: Stock_S_Encours | B44: Table de faits
A45: Nom | B45: Type | C45: Desr
A46: Location ID | B46: Int | C46: Identifiant boutique (FK)
A47: SKU | B47: Int | C47: Identifiant article (FK)
A48: Stock | B48: Int | C48: Quantité actuellement en stock (soit le lundi de la premiere semaine d'analyse)
...

Sheet DRP_V1
A1: Stock prévisionnel par article
B6: SAISIE | G6: INFORMATION
B7: Date | C7: SKU | D7: Location ID | G7: Libellé du SKU | H7: Famille de produit | I7: Nom de la boutique | J7: Unité de commande | K7: Order Lead Time: délai de livraison de la commande (en jours)
B8: 44739 | C8: 129208 | D8: 1202 | G8: =IFERROR(VLOOKUP(DRP_V1!C8,Article!A:F,2,FALSE), "SKU non trouvé") -> COUDE PVC | H8: =IFERROR(VLOOKUP(C8,Article!A:F,3,FALSE), "SKU non trouvé") -> SALLE DE BAINS | I8: =IFERROR(VLOOKUP(D8,Shop!A:C,2), "Location ID Non trouvé") -> BAYONNE | J8: =IFERROR(VLOOKUP(C8,Article!A:F,4,FALSE),"SKU non trouvé") -> UVC | K8: =IFERROR(VLOOKUP(C8,Article!A:F,5,FALSE),"SKU non trouvé") -> 14
B11: COMMANDE À PASSER / PROCHAIN ORDRE PLANIFIÉ | G11: DISTRIBUTION RESSOURCE PLANNING
B12: Date de passation | C12: Date de livraison souhaitée | D12: Quantité recommandée | I12: =B8 -> 44739 | J12: =I12+7 -> 44746 | K12: =J12+7 -> 44753 | L12: =K12+7 -> 44760 | M12: =L12+7 -> 44767 | N12: =M12+7 -> 44774 | O12: =N12+7 -> 44781 | P12: =O12+7 -> 44788
B13: =C13-K8 -> 44739 | C13: {=INDEX(I12:P12, MATCH(TRUE, IF((I12:P12 >= B8 + K8) * (I19:P19 > 0), TRUE, FALSE), 0))} -> 44753 | D13: =INDEX(I19:P19,MATCH(C13,I12:P12,0)) -> 60 | G13: Stock Initial | I13: =IFERROR(INDEX(Stock_S_Encours!C:C,MATCH(D8&"-"&C8,Stock_S_Encours!D:D,0)), "Combinaison <<SKU,Location ID>> non disponible") -> 74
G14: Stock projeté | J14: =IF(I13+I18+I19-I17>0,I13+I18+I19-I17,0) -> 32 | K14: =IF((J14+J18+J19)-J17>0,(J14+J18+J19)-J17,0) -> 0 | L14: =IF(((K14+K18+K19)-K17)>0,(K14+K18+K19)-K17,0) -> 0 | M14: =IF((L14+L18+L19)-L17>0,(L14+L18+L19)-L17,0) -> 0 | N14: =IF((M14+M18+M19)-M17>0,(M14+M18+M19)-M17,0) -> 0 | O14: =IF((N14+N18+N19)-N17>0,(N14+N18+N19)-N17,0) -> 0 | P14: =IF((O14+O18+O19)-O17>0,(O14+O18+O19)-O17,0) -> 0
G15: Rupture prévisionnelle | I15: =IF((I13+I18)-I17<0,(I13+I18)-I17,0) -> 0 | J15: =IF((J14+J18)-J17<0,(J14+J18)-J17,0) -> -9 | K15: =IF((K14+K18)-K17<0,(K1+K18)-K17,0) -> -60 | L15: =IF((L14+L18)-L17<0,(L14+L18)-L17,0) -> -103 | M15: =IF((M14+M18)-M17<0,(M14+M18)-M17,0) -> -84 | N15: =IF((N14+N18)-N17<0,(N14+N18)-N17,0) -> -42 | O15: =IF((O14+O18)-O17<0,(O14+O18)-O17,0) -> -98 | P15: =IF((P14+P18)-P17<0,(P14+P18)-P17,0) -> -109
G16: Couverture de Stock | I16: =IF(I14+I13+I18<0,0,IF(I15<0,(1+I15/I17)*7,IF(J15<0,7+(1+J15/J17)*7,IF(K15<0,14+(1+K15/K17)*7,IF(L15<0,21+(1+L15/L17)*7,IF(M15<0,28+(1+M15/M17)*7,IF(N15<0,35+(1+N15/N17)*7,IF(O15<0,42+(1+O15/O17)*7,IF(P15<0,49+(1+P15/P17)*7,56))))))))) -> 12.463415 | J16: =IF(J14++J18<0,0,IF(J15<0,(1+J15/J17)*7,IF(K15<0,7+(1+K15/K17)*7,IF(L15<0,14+(1+L15/L17)*7,IF(M15<0,21+(1+M15/M17)*7,IF(N15<0,28+(1+N15/N17)*7,IF(O15<0,35+(1+O15/O17)*7,IF(P15<0,42+(1+P15/P17)*7,49)))))))) -> 5.4634146 | K16: =IF(K14++K18<0,0,IF(K15<0,(1+K15/K17)*7,IF(L15<0,7+(1+L15/L17)*7,IF(M15<0,14+(1+M15/M17)*7,IF(N15<0,21+(1+N15/N17)*7,IF(O15<0,28+(1+O15/O17)*7,IF(P15<0,35+(1+P15/P17)*7,IF(Q15<0,42+(1+Q15/Q17)*7,49)))))))) -> 0 | L16: =IF(L14++L18<0,0,IF(L15<0,(1+L15/L17)*7,IF(M15<0,7+(1+M15/M17)*7,IF(N15<0,14+(1+N15/N17)*7,IF(O15<0,21+(1+O15/O17)*7,IF(P15<0,28+(1+P15/P17)*7,IF(Q15<0,35+(1+Q15/Q17)*7,IF(R15<0,42+(1+R15/R17)*7,49)))))))) -> 0 | M16: =IF(M14++M18<0,0,IF(M15<0,(1+M15/M17)*7,IF(N15<0,7+(1+N15/N17)*7,IF(O15<0,14+(1+O15/O17)*7,IF(P15<0,21+(1+P15/P17)*7,IF(Q15<0,28+(1+Q15/Q17)*7,IF(R15<0,35+(1+R15/R17)*7,IF(S15<0,42+(1+S15/S17)*7,49)))))))) -> 0 | N16: =IF(N14++N18<0,0,IF(N15<0,(1+N15/N17)*7,IF(O15<0,7+(1+O15/O17)*7,IF(P15<0,14+(1+P15/P17)*7,IF(Q15<0,21+(1+Q15/Q17)*7,IF(R15<0,28+(1+R15/R17)*7,IF(S15<0,35+(1+S15/S17)*7,IF(T15<0,42+(1+T15/T17)*7,49)))))))) -> 0 | O16: =IF(O14++O18<0,0,IF(O15<0,(1+O15/O17)*7,IF(P15<0,7+(1+P15/P17)*7,IF(Q15<0,14+(1+Q15/Q17)*7,IF(R15<0,21+(1+R15/R17)*7,IF(S15<0,28+(1+S15/S17)*7,IF(T15<0,35+(1+T15/T17)*7,IF(U15<0,42+(1+U15/U17)*7,49)))))))) -> 0 | P16: =IF(P14++P18<0,0,IF(P15<0,(1+P15/P17)*7,IF(Q15<0,7+(1+Q15/Q17)*7,IF(R15<0,14+(1+R15/R17)*7,IF(S15<0,21+(1+S15/S17)*7,IF(T15<0,28+(1+T15/T17)*7,IF(U15<0,35+(1+U15/U17)*7,IF(V15<0,42+(1+V15/V17)*7,49)))))))) -> 0
G17: Demande prévisionnelle | I17: =IFERROR(INDEX(Forecast!D:D,MATCH(D8&"-"&C8&"-"&INT(B8),Forecast!E:E,0)),"Pas de Demande Prévu ") -> 80 | J17: =IFERROR(INDEX(Forecast!D:D,MATCH(D8&"-"&C8&"-"&INT(J12),Forecast!E:E,0)),0) -> 41 | K17: =IFERROR(INDEX(Forecast!D:D,MATCH(D8&"-"&C8&"-"&INT(K12),Forecast!E:E,0)),0) -> 60 | L17: =IFERROR(INDEX(Forecast!D:D,MATCH(D8&"-"&C8&"-"&INT(L12),Forecast!E:E,0)),0) -> 103 | M17: =IFERROR(INDEX(Forecast!D:D,MATCH(D8&"-"&C8&"-"&INT(M12),Forecast!E:E,0)),0) -> 84 | N17: =IFERROR(INDEX(Forecast!D:D,MATCH(D8&"-"&C8&"-"&INT(N12),Forecast!E:E,0)),0) -> 42 | O17: =IFERROR(INDEX(Forecast!D:D,MATCH(D8&"-"&C8&"-"&INT(O12),Forecast!E:E,0)),0) -> 98 | P17: =IFERROR(INDEX(Forecast!D:D,MATCH(D8&"-"&C8&"-"&INT(P12),Forecast!E:E,0)),0) -> 109
G18: Ordre Ferme | I18: =IFERROR(INDEX(Commandes_EnCours!D:D,MATCH(D8&"-"&C8&"-"&INT(B8),Commandes_EnCours!E:E,0)),0) -> 38 | J18: =IFERROR(INDEX(Commandes_EnCours!D:D,MATCH(D8&"-"&C8&"-"&INT(J12),Commandes_EnCours!E:E,0)),0) -> 0 | K18: =IFERROR(INDEX(Commandes_EnCours!D:D,MATCH(D8&"-"&C8&"-"&INT(K12),Commandes_EnCours!E:E,0)),0) -> 0 | L18: =IFERROR(INDEX(Commandes_EnCours!D:D,MATCH(D8&"-"&C8&"-"&INT(L12),Commandes_EnCours!E:E,0)),0) -> 0 | M18: =IFERROR(INDEX(Commandes_EnCours!D:D,MATCH(D8&"-"&C8&"-"&INT(M12),Commandes_EnCours!E:E,0)),0) -> 0 | N18: =IFERROR(INDEX(Commandes_EnCours!D:D,MATCH(D8&"-"&C8&"-"&INT(N12),Commandes_EnCours!E:E,0)),0) -> 0 | O18: =IFERROR(INDEX(Commandes_EnCours!D:D,MATCH(D8&"-"&C8&"-"&INT(O12),Commandes_EnCours!E:E,0)),0) -> 0 | P18: =IFERROR(INDEX(Commandes_EnCours!D:D,MATCH(D8&"-"&C8&"-"&INT(P12),Commandes_EnCours!E:E,0)),0) -> 0
G19: Besoin Net | I19: =ABS(I15) -> 0 | J19: =ABS(J15) -> 9 | K19: =ABS(K15) -> 60 | L19: =ABS(L15) -> 103 | M19: =ABS(M15) -> 84 | N19: =ABS(N15) -> 42 | O19: =ABS(O15) -> 98 | P19: =ABS(P15) -> 109
G21: Couverture moyenne | H21: =AVERAGE(I16:P16) -> 2.2408537
G22: Variation du stock | H22: =(P14-I13)/I13 -> -1
A38: Encadré principal: informations importantes -Le stock initial correspond au stock de début de la semaine en cours. -La rupture prévisionnelle correspond à la quantité en rupture. Cela signifie que le stock et les ordres fermes de la semaine ne permettent pas de couvrir les sorties prévues. S’il n’y a pas de rupture, alors la valeur doit afficher 0. -La couverture de stock représente la durée (en nombre de jours) entre la date de l’en-tête de colonne et la prochaine rupture. Cela signifie que si votre stock vous permet de couvrir ⅔ de votre demande hebdomadaire avant de tomber en rupture, il faudra compter ⅔ de semaine dans votre couverture de stock. -L'ordre ferme correspond aux commandes déjà passées par le service. -Le besoin net correspond ici à la rupture prévisionnelle en absolu. C’est la quantité à réceptionner sur la semaine pour ne pas tomber en rupture. Il doit être réintégré dans le calcul du stock projeté de la semaine suivante, au même titre que les ordres fermes.

Sheet Feuil2

Sheet DRP_V2
A1: Stock prévisionnel par article
B6: SAISIE | G6: INFORMATION
B7: Date | C7: SKU | D7: Location ID | G7: Libellé du SKU | H7: Famille de produit | I7: Nom de la boutique | J7: Unité de commande | K7: Order Lead Time: délai de livraison de la commande (en jours) | L7: le stock de sécurité (SS) | M7: le minimum de commande (MOQ)
B8: 44739 | C8: 141622 | D8: 1211 | G8: =IFERROR(VLOOKUP(DRP_V2!C8,Article!A:F,2,FALSE), "SKU non trouvé") -> BONDE LAVABO | H8: =IFERROR(VLOOKUP(C8,Article!A:F,3,FALSE), "SKU non trouvé") -> SALLE DE BAINS | I8: =IFERROR(VLOOKUP(D8,Shop!A:C,2), "Location ID Non trouvé") -> TOULON | J8: =IFERROR(VLOOKUP(C8,Article!A:F,4,FALSE),"SKU non trouvé") -> UVC | K8: =IFERROR(VLOOKUP(C8,Article!A:F,5,FALSE),"SKU non trouvé") -> 7 | L8: =VLOOKUP(C8,'[1]Article-Paramètre'!$A:$C,3,FALSE) -> 4 | M8: =VLOOKUP(C8,'[1]Article-Paramètre'!$A:$C,2,FALSE) -> 10
B11: COMMANDE À PASSER / PROCHAIN ORDRE PLANIFIÉ | G11: DISTRIBUTION RESSOURCE PLANNING
B12: Date de passation | C12: Date de livraison souhaitée | D12: Quantité recommandée | I12: =B8 -> 44739 | J12: =I12+7 -> 44746 | K12: =J12+7 -> 44753 | L12: =K12+7 -> 44760 | M12: =L12+7 -> 44767 | N12: =M12+7 -> 44774 | O12: =N12+7 -> 44781 | P12: =O12+7 -> 44788
B13: =IFERROR(C13-K8,"") -> 44767 | C13: {=IFERROR(INDEX(I12:P12,MATCH(TRUE,IF((I12:P12>=B8+K8)*(I22:P22>0),TRUE,FALSE),0)),"Aucune livraison encours")} -> 44774 | D13: =IFERROR(INDEX(I22:P22,MATCH(C13,I12:P12,0)),"") -> 10 | G13: Stock Initial | I13: =IFERROR(INDEX(Stock_S_Encours!C:C,MATCH(D8&"-"&C8,Stock_S_Encours!D:D,0)), 0) -> 110
G14: Stock projeté | J14: =IF(I13+I18+I22-I17>0,I13+I18+I22-I17,0) -> 85 | K14: =IF(J14+J18+J22-J17>0,J14+J18+J22-J17,0) -> 67 | L14: =IF(K14+K18+K22-K17>0,K14+K18+K22-K17,0) -> 66 | M14: =IF(L14+L18+L22-L17>0,L14+L18+L22-L17,0) -> 52 | N14: =IF(M14+M18+M22-M17>0,M14+M18+M22-M17,0) -> 28 | O14: =IF(N14+N18+N22-N17>0,N14+N18+N22-N17,0) -> 16 | P14: =IF(O14+O18+O22-O17>0,O14+O18+O22-O17,0) -> 10
G15: Rupture prévisionnelle | I15: =IF((I13+I18)-I17<0,(I13+I18)-I17,0) -> 0 | J15: =IF((J14+J18)-J17<0,(J14+J18)-J17,0) -> 0 | K15: =IF((K14+K18)-K17<0,(K14+K18)-K17,0) -> 0 | L15: =IF((L14+L18)-L17<0,(L14+L18)-L17,0) -> 0 | M15: =IF((M14+M18)-M17<0,(M14+M18)-M17,0) -> 0 | N15: =IF((N14+N18)-N17<0,(N14+N18)-N17,0) -> 0 | O15: =IF((O14+O18)-O17<0,(O14+O18)-O17,0) -> 0 | P15: =IF((P14+P18)-P17<0,(P14+P18)-P17,0) -> -13
G16: Couverture de Stock | I16: =IF(I14+I13+I18<0,0,IF(I15<0,(1+I15/I17)*7,IF(J15<0,7+(1+J15/J17)*7,IF(K15<0,14+(1+K15/K17)*7,IF(L15<0,21+(1+L15/L17)*7,IF(M15<0,28+(1+M15/M17)*7,IF(N15<0,35+(1+N15/N17)*7,IF(O15<0,42+(1+O15/O17)*7,IF(P15<0,49+(1+P15/P17)*7,56))))))))) -> 52.043478 | J16: =IF(J14+J13+J18<0,0,IF(J15<0,(1+J15/J17)*7,IF(K15<0,7+(1+K15/K17)*7,IF(L15<0,14+(1+L15/L17)*7,IF(M15<0,21+(1+M15/M17)*7,IF(N15<0,28+(1+N15/N17)*7,IF(O15<0,35+(1+O15/O17)*7,IF(P15<0,42+(1+P15/P17)*7,49)))))))) -> 45.043478 | K16: =IF(K14+K13+K18<0,0,IF(K15<0,(1+K15/K17)*7,IF(L15<0,7+(1+L15/L17)*7,IF(M15<0,14+(1+M15/M17)*7,IF(N15<0,21+(1+N15/N17)*7,IF(O15<0,28+(1+O15/O17)*7,IF(P15<0,35+(1+P15/P17)*7,42))))))) -> 38.043478 | L16: =IF(L14+L13+L18<0,0,IF(L15<0,(1+L15/L17)*7,IF(M15<0,7+(1+M15/M17)*7,IF(N15<0,14+(1+N15/N17)*7,IF(O15<0,21+(1+O15/O17)*7,IF(P15<0,28+(1+P15/P17)*7,35)))))) -> 31.043478 | M16: =IF(M14+M13+M18<0,0,IF(M15<0,(1+M15/M17)*7,IF(N15<0,7+(1+N15/N17)*7,IF(O15<0,14+(1+O15/O17)*7,IF(P15<0,21+(1+P15/P17)*7,28))))) -> 24.043478 | N16: =IF(N14+N13+N18<0,0,IF(N15<0,(1+N15/N17)*7,IF(O15<0,7+(1+O15/O17)*7,IF(P15<0,14+(1+P15/P17)*7,21)))) -> 17.043478 | O16: =IF(O14+O13+O18<0,0,IF(O15<0,(1+O15/O17)*7,IF(P15<0,7+(1+P15/P17)*7,14))) -> 10.043478 | P16: =IF(P14+P13+P18<0,0,IF(P15<0,(1+P15/P17)*7,56)) -> 3.0434783
G17: Demande prévisionnelle | I17: =IFERROR(INDEX(Forecast!D:D,MATCH(D8&"-"&C8&"-"&INT(B8),Forecast!E:E,0)),0) -> 25 | J17: =IFERROR(INDEX(Forecast!D:D,MATCH(D8&"-"&C8&"-"&INT(J12),Forecast!E:E,0)),0) -> 18 | K17: =IFERROR(INDEX(Forecast!D:D,MATCH(D8&"-"&C8&"-"&INT(K12),Forecast!E:E,0)),0) -> 22 | L17: =IFERROR(INDEX(Forecast!D:D,MATCH(D8&"-"&C8&"-"&INT(L12),Forecast!E:E,0)),0) -> 14 | M17: =IFERROR(INDEX(Forecast!D:D,MATCH(D8&"-"&C8&"-"&INT(M12),Forecast!E:E,0)),0) -> 24 | N17: =IFERROR(INDEX(Forecast!D:D,MATCH(D8&"-"&C8&"-"&INT(N12),Forecast!E:E,0)),0) -> 22 | O17: =IFERROR(INDEX(Forecast!D:D,MATCH(D8&"-"&C8&"-"&INT(O12),Forecast!E:E,0)),0) -> 16 | P17: =IFERROR(INDEX(Forecast!D:D,MATCH(D8&"-"&C8&"-"&INT(P12),Forecast!E:E,0)),0) -> 23
G18: Ordre Ferme | I18: =IFERROR(INDEX(Commandes_EnCours!D:D,MATCH(D8&"-"&C8&"-"&INT(B8),Commandes_EnCours!E:E,0)),0) -> 0 | J18: =IFERROR(INDEX(Commandes_EnCours!D:D,MATCH(D8&"-"&C8&"-"&INT(J12),Commandes_EnCours!E:E,0)),0) -> 0 | K18: =IFERROR(INDEX(Commandes_EnCours!D:D,MATCH(D8&"-"&C8&"-"&INT(K12),Commandes_EnCours!E:E,0)),0) -> 21 | L18: =IFERROR(INDEX(Commandes_EnCours!D:D,MATCH(D8&"-"&C8&"-"&INT(L12),Commandes_EnCours!E:E,0)),0) -> 0 | M18: =IFERROR(INDEX(Commandes_EnCours!D:D,MATCH(D8&"-"&C8&"-"&INT(M12),Commandes_EnCours!E:E,0)),0) -> 0 | N18: =IFERROR(INDEX(Commandes_EnCours!D:D,MATCH(D8&"-"&C8&"-"&INT(N12),Commandes_EnCours!E:E,0)),0) -> 0 | O18: =IFERROR(INDEX(Commandes_EnCours!D:D,MATCH(D8&"-"&C8&"-"&INT(O12),Commandes_EnCours!E:E,0)),0) -> 0 | P18: =IFERROR(INDEX(Commandes_EnCours!D:D,MATCH(D8&"-"&C8&"-"&INT(P12),Commandes_EnCours!E:E,0)),0) -> 0
G19: Besoin Net | I19: =ABS(I21) -> 0 | J19: =ABS(J21) -> 0 | K19: =ABS(K21) -> 0 | L19: =ABS(L21) -> 0 | M19: =ABS(M21) -> 0 | N19: =ABS(N21) -> 6.5714286 | O19: =ABS(O21) -> 9.1428571 | P19: =ABS(P21) -> 26.142857
G20: le stock de sécurité calculé | I20: =(L8/7)*I17 -> 14.285714 | J20: =(L8/7)*J17 -> 10.285714 | K20: =(L8/7)*K17 -> 12.571429 | L20: =(L8/7)*L17 -> 8 | M20: =(L8/7)*M17 -> 13.714286 | N20: =(L8/7)*N17 -> 12.571429 | O20: =(L8/7)*O17 -> 9.1428571 | P20: =(L8/7)*P17 -> 13.142857
G21: le sous-stock; | I21: =IF((I13+I18)-(I17+I20)>0,0,(I13+I18)-(I17+I20)) -> 0 | J21: =IF((J14+J18)-(J17+J20)>0,0,(J14+J18)-(J17+J20)) -> 0 | K21: =IF((K14+K18)-(K17+K20)>0,0,(K14+K18)-(K17+K20)) -> 0 | L21: =IF((L14+L18)-(L17+L20)>0,0,(L14+L18)-(L17+L20)) -> 0 | M21: =IF((M14+M18)-(M17+M20)>0,0,(M14+M18)-(M17+M20)) -> 0 | N21: =IF((N14+N18)-(N17+N20)>0,0,(N14+N18)-(N17+N20)) -> -6.5714286 | O21: =IF((O14+O18)-(O17+O20)>0,0,(O14+O18)-(O17+O20)) -> -9.1428571 | P21: =IF((P14+P18)-(P17+P20)>0,0,(P14+P18)-(P17+P20)) -> -26.142857
G22: ordre planifié | I22: =IF(I19>0,IF(I19>$M$8,I19,$M$8),0) -> 0 | J22: =IF(J19>0,IF(J19>$M$8,J19,$M$8),0) -> 0 | K22: =IF(K19>0,IF(K19>$M$8,K19,$M$8),0) -> 0 | L22: =IF(L19>0,IF(L19>$M$8,L19,$M$8),0) -> 0 | M22: =IF(M19>0,IF(M19>$M$8,M19,$M$8),0) -> 0 | N22: =IF(N19>0,IF(N19>$M$8,N19,$M$8),0) -> 10 | O22: =IF(O19>0,IF(O19>$M$8,O19,$M$8),0) -> 10 | P22: =IF(P19>0,IF(P19>$M$8,P19,$M$8),0) -> 26.142857
G24: Couverture moyenne | H24: =AVERAGE(I16:P16) -> 27.543478 | J24: La référence du fournisseur | K24: La distance en Km | L24: Le nom du transporteur choisi | M24: Le coût associé(€)
G25: Variation du stock | H25: =(P14-I13)/I13 -> -0.90909091 | J25: =VLOOKUP(C8,Article!A:F,6,FALSE) -> 12576 | K25: {=IFERROR(INDEX('Fournisseurs-Magasin'!C:C,MATCH(TRUE,IF((J25='Fournisseurs-Magasin'!A:A)*(DRP_V2!D8='Fournisseurs-Magasin'!B:B),TRUE,FALSE),0)),"")} -> 869 | L25: {=INDEX(Transporteurs!A2:A9, MATCH(MIN($K$25 * Transporteurs!C2:C9 +Transporteurs!B2:B9),$K$25 * Transporteurs!C2:C9 +Transporteurs!B2:B9, 0))} -> AV | M25: {=MIN($K$25 * Transporteurs!C2:C9 + Transporteurs!B2:B9)} -> 944
A42: Encadré principal: informations importantes -Le stock initial correspond au stock de début de la semaine en cours. -La rupture prévisionnelle correspond à la quantité en rupture. Cela signifie que le stock et les ordres fermes de la semaine ne permettent pas de couvrir les sorties prévues. S’il n’y a pas de rupture, alors la valeur doit afficher 0. -La couverture de stock représente la durée (en nombre de jours) entre la date de l’en-tête de colonne et la prochaine rupture. Cela signifie que si votre stock vous permet de couvrir ⅔ de votre demande hebdomadaire avant de tomber en rupture, il faudra compter ⅔ de semaine dans votre couverture de stock. -L'ordre ferme correspond aux commandes déjà passées par le service. -Le besoin net correspond ici à la rupture prévisionnelle en absolu. C’est la quantité à réceptionner sur la semaine pour ne pas tomber en rupture. Il doit être réintégré dans le calcul du stock projeté de la semaine suivante, au même titre que les ordres fermes.

Sheet Feuil3
A1: Riana Mamy12:04
A2: Critères d’évaluation de la mission Barre Analyser l'approvisionnement de l'entreprise en produits afin d'optimiser la supply chain Le DRP V1 peut être validé si : ❒ Les encadrés de saisie, d’informations, de passation de commande et l’encadré principal apparaissent sur la même feuille. ❒ Le choix de clé de jointure permet de retrouver les données de l’encadré principal. Exemples de clés de jointure : SKU et Location ID SKU, Location ID et date ❒ Les encadrés sont dynamiques et correspondent au corrigé en fonction du périmètre saisi. ❒ Le calcul du stock projeté correspond au mode de calcul suivant : stock de début (S-1) + ordres fermes (S-1) - demande prévisionnelle S-1 ❒ Le besoin net correspond aux quantités manquantes pour finir la semaine. ❒ La couverture de stock est donnée à la précision “jour”. ❒ La date de passation de commande est calculée à partir de la date de livraison souhaitée et du lead time. L'histogramme et son encadré peuvent être validés si : ❒ L’histogramme est titré et contient une légende. ❒ Le stock initial et le stock projeté apparaissent graphiquement dans un histogramme. ❒ Le stock initial et le stock projeté sont représentés par deux couleurs différentes. ❒ L’histogramme est accompagné d’un encadré indiquant la couverture moyenne et la variation du stock prévue, de manière dynamique. Le DRP V2 peut être validé si : ❒ Les nouvelles informations (stock de sécurité et MOQ) ont été intégrées dans l’encadré d’informations, de façon dynamique. ❒ Le sous-stock a été calculé correctement et correspond au mode de calcul suivant : (stock global + ordres fermes) - (demande prévisionnelle + stock de sécurité calculé) ❒ Le DRP a été modifié afin de baser le calcul du besoin net sur le sous-stock. ❒ La ligne “ordres planifiés” se base sur le besoin net. ❒ Les éléments critiques (rupture et commande hors délais) ont été mis en évidence par des formats conditionnels, et ce de façon dynamique. Exemples de formats conditionnels: gras rouge La V2 de l'histogramme et son encadré peuvent être validés si: ❒ La représentation graphique des données du stock projeté correspond aux modifications effectuées dans la V2 du DRP. ❒ Le calcul de la couverture moyenne et de la variation de stock prévue intègre correctement les modifications de la V2. Analyser les coûts de transport en tenant compte des contraintes afin de recommander des solutions Le DRP V2 avec les coûts de transport peut être validé si : ❒ L’encadré de visualisation du meilleur transporteur est présent sur la feuille principale. ❒ L’encadré de visualisation du meilleur transporteur affiche le nom du transporteur, la distance en Km entre le fournisseur et le magasin et le coût associé. Soutenance Barre Pour ce projet, l’étudiant présentera son travail devant un évaluateur. En tant qu’évaluateur, reprenez les critères d’évaluation présents dans ce guide mentor et vérifiez qu’ils soient tous validés. Si vous avez un doute sur la surutilisation de l’intelligence artificielle dans les livrables, assurez-vous de poser une des questions suivantes à l’étudiant : Comment avez-vous fait pour [partie ou tout d’un livrable]...? Quelle a été la méthodologie suivie pour réaliser [partie ou tout d’un livrable] ? Quelles ont été les différentes étapes que vous avez suivies pour élaborer [partie ou tout d’un livrable] ? Vous pouvez les lui poser durant les 10 min de discussion ou les 5 minutes de débrief de la soutenance. Pour la structure de la soutenance, référez-vous à la section Soutenance du scénario du projet. Pour faciliter votre travail, voici les critères d’évaluation que vous devez vérifier pendant la soutenance, en posant des questions spécifiques à l’étudiant. ❒ L’étudiant est capable d’expliquer le mode de construction des V1 et V2 de son fichier Excel pendant la soutenance. ❒ L’étudiant a identifié et est capable d’expliquer 1 cas de bonne pratique et 2 cas de mauvaises pratiques de passation de commandes. Exemple de bonne pratique de passation de commande: L’ordre ferme a été passé à temps et correspond au besoin : SKU 23393 pour la boutique 1210. Exemples de mauvaises pratiques de passation de commande: Dates de commandes dépassées: SKU 23393 pour les boutiques 1204, 1203 et 1202. Ordre ferme passé en quantité insuffisante: SKU 23393 pour la boutique 1211 Ordre ferme passé sans besoin spécifique, donc surstock: SKU 23393 pour le site 1208 Pour les étudiants les plus à l’aise, vous pouvez également poser des questions afin de creuser certains points. Attention, ces questions ne peuvent pas justifier d’un refus de la soutenance : Comment interprétez-vous l’impact des MOQ sur la couverture de stock ? (ex : il augmente la couverture de stock au moment de la réception si le besoin initial était inférieur au MOQ). À votre avis, lorsque plusieurs besoins nets se succèdent, que pourrait faire l’approvisionneur lors de sa passation de commande ? (ex : consolider les besoins dans une seule commande / ordre planifié) : Quelle est la conséquence ? (ex : augmenter le niveau de stock à réception, mais peut permettre potentiellement d’optimiser le transport et de réduire le nombre de réception en boutique). Une soutenance mérite un refus dans les cas suivants : Critères d’évaluation non validés pour une ou plusieurs compétences. Plagiat (veillez à poser des questions méthodologiques ou sur le raisonnement de la solution pour vous assurer que le travail a bien été réalisé par l’étudiant). Une présentation en dessous de 10 minutes ou au-dessus de 20 minutes. Néanmoins, une tolérance de +/- 20 % est permise, selon les cas.
A3: Votre message
B12: Riana Mamy12:04
B13: Critères d’évaluation de la mission Barre Analyser l'approvisionnement de l'entreprise en produits afin d'optimiser la supply chain Le DRP V1 peut être validé si : ❒ Les encadrés de saisie, d’informations, de passation de commande et l’encadré principal apparaissent sur la même feuille. ❒ Le choix de clé de jointure permet de retrouver les données de l’encadré principal. Exemples de clés de jointure : SKU et Location ID SKU, Location ID et date ❒ Les encadrés sont dynamiques et correspondent au corrigé en fonction du périmètre saisi. ❒ Le calcul du stock projeté correspond au mode de calcul suivant : stock de début (S-1) + ordres fermes (S-1) - demande prévisionnelle S-1 ❒ Le besoin net correspond aux quantités manquantes pour finir la semaine. ❒ La couverture de stock est donnée à la précision “jour”. ❒ La date de passation de commande est calculée à partir de la date de livraison souhaitée et du lead time. L'histogramme et son encadré peuvent être validés si : ❒ L’histogramme est titré et contient une légende. ❒ Le stock initial et le stock projeté apparaissent graphiquement dans un histogramme. ❒ Le stock initial et le stock projeté sont représentés par deux couleurs différentes. ❒ L’histogramme est accompagné d’un encadré indiquant la couverture moyenne et la variation du stock prévue, de manière dynamique. Le DRP V2 peut être validé si : ❒ Les nouvelles informations (stock de sécurité et MOQ) ont été intégrées dans l’encadré d’informations, de façon dynamique. ❒ Le sous-stock a été calculé correctement et correspond au mode de calcul suivant : (stock global + ordres fermes) - (demande prévisionnelle + stock de sécurité calculé) ❒ Le DRP a été modifié afin de baser le calcul du besoin net sur le sous-stock. ❒ La ligne “ordres planifiés” se base sur le besoin net. ❒ Les éléments critiques (rupture et commande hors délais) ont été mis en évidence par des formats conditionnels, et ce de façon dynamique. Exemples de formats conditionnels: gras rouge La V2 de l'histogramme et son encadré peuvent être validés si: ❒ La représentation graphique des données du stock projeté correspond aux modifications effectuées dans la V2 du DRP. ❒ Le calcul de la couverture moyenne et de la variation de stock prévue intègre correctement les modifications de la V2. Analyser les coûts de transport en tenant compte des contraintes afin de recommander des solutions Le DRP V2 avec les coûts de transport peut être validé si : ❒ L’encadré de visualisation du meilleur transporteur est présent sur la feuille principale. ❒ L’encadré de visualisation du meilleur transporteur affiche le nom du transporteur, la distance en Km entre le fournisseur et le magasin et le coût associé. Soutenance Barre Pour ce projet, l’étudiant présentera son travail devant un évaluateur. En tant qu’évaluateur, reprenez les critères d’évaluation présents dans ce guide mentor et vérifiez qu’ils soient tous validés. Si vous avez un doute sur la surutilisation de l’intelligence artificielle dans les livrables, assurez-vous de poser une des questions suivantes à l’étudiant : Comment avez-vous fait pour [partie ou tout d’un livrable]...? Quelle a été la méthodologie suivie pour réaliser [partie ou tout d’un livrable] ? Quelles ont été les différentes étapes que vous avez suivies pour élaborer [partie ou tout d’un livrable] ? Vous pouvez les lui poser durant les 10 min de discussion ou les 5 minutes de débrief de la soutenance. Pour la structure de la soutenance, référez-vous à la section Soutenance du scénario du projet. Pour faciliter votre travail, voici les critères d’évaluation que vous devez vérifier pendant la soutenance, en posant des questions spécifiques à l’étudiant. ❒ L’étudiant est capable d’expliquer le mode de construction des V1 et V2 de son fichier Excel pendant la soutenance. ❒ L’étudiant a identifié et est capable d’expliquer 1 cas de bonne pratique et 2 cas de mauvaises pratiques de passation de commandes. Exemple de bonne pratique de passation de commande: L’ordre ferme a été passé à temps et correspond au besoin : SKU 23393 pour la boutique 1210. Exemples de mauvaises pratiques de passation de commande: Dates de commandes dépassées: SKU 23393 pour les boutiques 1204, 1203 et 1202. Ordre ferme passé en quantité insuffisante: SKU 23393 pour la boutique 1211 Ordre ferme passé sans besoin spécifique, donc surstock: SKU 23393 pour le site 1208 Pour les étudiants les plus à l’aise, vous pouvez également poser des questions afin de creuser certains points. Attention, ces questions ne peuvent pas justifier d’un refus de la soutenance : Comment interprétez-vous l’impact des MOQ sur la couverture de stock ? (ex : il augmente la couverture de stock au moment de la réception si le besoin initial était inférieur au MOQ). À votre avis, lorsque plusieurs besoins nets se succèdent, que pourrait faire l’approvisionneur lors de sa passation de commande ? (ex : consolider les besoins dans une seule commande / ordre planifié) : Quelle est la conséquence ? (ex : augmenter le niveau de stock à réception, mais peut permettre potentiellement d’optimiser le transport et de réduire le nombre de réception en boutique). Une soutenance mérite un refus dans les cas suivants : Critères d’évaluation non validés pour une ou plusieurs compétences. Plagiat (veillez à poser des questions méthodologiques ou sur le raisonnement de la solution pour vous assurer que le travail a bien été réalisé par l’étudiant). Une présentation en dessous de 10 minutes ou au-dessus de 20 minutes. Néanmoins, une tolérance de +/- 20 % est permise, selon les cas.
B14: Votre message
K25: Riana Mamy12:26
K26: [@[Prix Fixe €]]+[@[€/km au-delà fixe]]*'DashboardStock 2'!$C$16

Sheet Feuil1
A1: =IF(I14+I13+I18<0,0,IF(I15<0,(1+I15/I17)*7,IF(J15<0,7+(1+J15/J17)*7,IF(K15<0,14+(1+K15/K17)*7,IF(L15<0,21+(1+L15/L17)*7,IF(M15<0,28+(1+M15/M17)*7,IF(N15<0,35+(1+N15/N17)*7,IF(O15<0,42+(1+O15/O17)*7,IF(P15<0,49+(1+P15/P17)*7,56))))))))) -> 56
A2: Riana MamyRiana Mamy13:25
A3: ligne 13 : Stock projeté
A5: Riana MamyRiana Mamy13:26
A6: ligne 12 : stock initial
A7: Riana MamyRiana Mamy13:26
A8: ligne 17 : Ordre ferme
A10: ligne 12 | B10: stock initial | L10: =IF(I14+I13+I18<0,0,IF(I15<0,(1+I15/I17)*7,IF(J15<0,7+(1+J15/J17)*7,IF(K15<0,14+(1+K15/K17)*7,IF(L15<0,21+(1+L15/L17)*7,IF(M15<0,28+(1+M15/M17)*7,IF(N15<0,35+(1+N15/N17)*7,IF(O15<0,42+(1+O15/O17)*7,IF(P15<0,49+(1+P15/P17)*7,56))))))))) -> 56
A11: ligne13 | B11: stock projeté | L11: Riana Mamy13:25
A12: ligne 14 | B12: rupture prévisionnelle | L12: ligne 13 : Stock projeté
A13: ligne 15 | B13: couverture de stock | L13: Riana Mamy13:26
A14: ligne 16 | B14: demande prévisionnelle | L14: ligne 12 : stock initial
A15: ligne 17 | B15: ordre ferme | L15: Riana Mamy13:26
A16: ligne 18 | B16: besoin net | L16: ligne 17 : Ordre ferme
L17: Riana Mamy13:27
L18: ligne 14 : Rupture prévisionnelle
L19: Riana Mamy13:27
L20: ligne 16 : Demande prévisionnelle
L21: Riana Mamy13:28
L22: formule Couverture de Stock
